Workbook

Sheet BÁO GIÁ CHỊ XUYÊN
D2: CHUYÊN SẢN XUẤT: CỬA CUỐN CÔNG NGHỆ ÚC/ ĐỨC - CỬA MẮT VÕNG/ SONG NGANG
D3: Văn phòng & nhà xưởng: Số 12B đường số 2, P. Bình Hưng Hòa, Q. Bình Tân, TP.HCM
D4: Điện thoại: 096 515 9595 - 0907 939 989
D5: Website: www.alumdoor.vn
B7: BẢNG BÁO GIÁ
B9: Tên khách hàng: | C9: ANH BẢO | G9: Ngày đặt hàng: | I9: Số hóa đơn:
B10: Điện thoại: | G10: Ngày giao hàng: | I10: Số đơn đặt hàng:
B11: Địa chỉ giao hàng: | G11: Phụ trách bán hàng:
B13: NGÀY GIAO HÀNG | C13: SẢN PHẨM & QUY CÁCH | D13: CAO PHỦ BÌ (M) | E13: RỘNG PBRAY(M) | F13: SỐ LƯỢNG | G13: KHỐI LƯỢNG | H13: ĐƠN GIÁ | I13: ĐVT | J13: THÀNH TIỀN
C14: AL652 - MS: "BÁO SAU" | D14: 4 | E14: 6.05 | F14: 1 | G14: =E14*D14 -> 24.2 | H14: 1420000 | I14: M2 | J14: =H14*G14 -> 34364000
C15: RAY HỘP TD | D15: 3.9 | F15: 2 | I15: M
C16: TRỤC 140 | E16: 6.1 | F16: 1 | I16: M
C17: PULY 140 | F17: 9 | I17: CÁI
C18: BỘ TỰ DỪNG | F18: 1 | I18: BỘ
C19: CON LĂN | F19: 1 | I19: CẶP
C20: BÌNH LƯU ĐIỆN | F20: 1 | H20: 2500000 | I20: CÁI | J20: =H20 -> 2500000
C21: MOTOR AC 800KG | F21: 1 | I21: BỘ | J21: 4000000
B22: TỔNG ĐƠN HÀNG | J22: =SUM(J14:J21) -> 40864000
H24: TP.HCM, Ngày 18 tháng 10 năm 2025
I25: Bên bán
G26: CÔNG TY TNHH HƯNG DƯƠNG PHÁT | T26: 2409000
C30: Cám ơn sự tin tưởng của khách hàng dành cho chúng tôi!

Sheet Sheet2
D2: CHUYÊN SẢN XUẤT: CỬA CUỐN CÔNG NGHỆ ÚC/ ĐỨC - CỬA MẮT VÕNG/ SONG NGANG
D3: Văn phòng & nhà xưởng: Số 12B đường số 2, P. Bình Hưng Hòa, Q. Bình Tân, TP.HCM
D4: Điện thoại: 096 515 9595 - 0907 939 989
D5: Website: www.alumdoor.vn
B7: BẢNG BÁO GIÁ
B9: Tên khách hàng: | C9: CTY SÁU HỒNG | G9: Ngày đặt hàng: | I9: Số hóa đơn:
B10: Điện thoại: | G10: Ngày giao hàng: | I10: Số đơn đặt hàng:
B11: Địa chỉ giao hàng: | G11: Phụ trách bán hàng: Lê Thúy
B13: NGÀY GIAO HÀNG | C13: SẢN PHẨM & QUY CÁCH | D13: CAO PHỦ BÌ (M) | E13: RỘNG PBRAY(M) | F13: SỐ LƯỢNG | G13: KHỐI LƯỢNG | H13: ĐƠN GIÁ | I13: ĐVT | J13: THÀNH TIỀN | K13: CÒN LẠI
C14: AL548N - MS: GS | D14: 4 | E14: 7 | F14: 1 | G14: =E14*D14 -> 28 | H14: 1244000 | I14: M2 | J14: =H14*G14 -> 34832000 | K14: =J14 -> 34832000
C15: CK 15% | F15: 1 | G15: =G14 -> 28 | H15: =H14*-15% -> -186600 | I15: M2 | J15: =H15*G15 -> -5224800 | K15: =J15+K14 -> 29607200
C16: RAY HỘP TD | D16: 3.9 | F16: 2 | H16: 170000 | I16: M | J16: =H16*F16*D16 -> 1326000 | K16: =J16+K15 -> 30933200
C17: PULY 140 | F17: 10 | H17: 29000 | I17: CÁI | J17: =H17*F17 -> 290000 | K17: =J17+K16 -> 31223200
C18: TRỤC 140 | E18: 7.1 | F18: 1 | H18: 250000 | I18: M | J18: =H18*E18 -> 1775000 | K18: =J18+K17 -> 32998200
C19: BỘ TỰ DỪNG | F19: 1 | H19: 80000 | I19: BỘ | J19: =H19 -> 80000 | K19: =J19+K18 -> 33078200
C20: CON LĂN | F20: 1 | H20: 90000 | I20: CẶP | J20: =H20*F20 -> 90000 | K20: =J20+K19 -> 33168200
B21: TỔNG ĐƠN HÀNG | J21: =SUM(J14:J20) -> 33168200
B23: ● Ngân hàng TMCP Quân đội (MB Bank) | H23: TP.HCM, Ngày 18 tháng 10 năm 2025
B24: Số TK 7030102681004 - Chủ TK LÊ MỘNG THUÝ | I24: Bên bán
B25: ● Ngân hàng Techcombank | F25: CÔNG TY TNHH INTERNATIONAL ALUMINUM APPLICATION (IAA) | U25: 2409000
B26: Số TK 19034379719018 - Chủ TK LÊ MỘNG THUÝ
B27: ● Ngân hàng ACB
B28: Số TK 8889886 - Chủ TK LÊ MỘNG THUÝ
C29: Cám ơn sự tin tưởng của khách hàng dành cho chúng tôi!

Sheet BÁO GIÁ
D2: CHUYÊN SẢN XUẤT: CỬA CUỐN CÔNG NGHỆ ÚC/ ĐỨC - CỬA MẮT VÕNG/ SONG NGANG
D3: Văn phòng & nhà xưởng: Số 12B đường số 2, P. Bình Hưng Hòa, Q. Bình Tân, TP.HCM
D4: Điện thoại: 096 515 9595 - 0907 939 989
D5: Website: www.alumdoor.vn
B7: BẢNG BÁO GIÁ
B9: Tên khách hàng: | C9: CTY SÁU HỒNG | G9: Ngày đặt hàng: | I9: Số hóa đơn:
B10: Điện thoại: | G10: Ngày giao hàng: | I10: Số đơn đặt hàng:
B11: Địa chỉ giao hàng: | G11: Phụ trách bán hàng: Lê Thúy
B13: NGÀY GIAO HÀNG | C13: SẢN PHẨM & QUY CÁCH | D13: CAO PHỦ BÌ (M) | E13: RỘNG PBRAY(M) | F13: SỐ LƯỢNG | G13: KHỐI LƯỢNG | H13: ĐƠN GIÁ | I13: ĐVT | J13: THÀNH TIỀN | K13: CÒN LẠI
C14: CỬA LƯỚI MV INOX 304 (RAY U80) - CL1 (TRỌN BỘ) Thương hiệu Alumdoor, Ống phi 12.7mm dày 1.0 | D14: 3.5 | E14: 4.9 | F14: 2 | G14: =E14*D14 -> 17.15 | H14: 1490000 | I14: M2 | J14: =H14*G14*F14 -> 51107000 | K14: =J14 -> 51107000
C15: CỬA LƯỚI MV INOX 304 (RAY U80) - CL3 (TRỌN BỘ) Thương hiệu Alumdoor, Ống phi 12.7mm dày 1.0 | D15: 3.5 | E15: 2.56 | F15: 1 | G15: =E15*D15 -> 8.96 | H15: 1490000 | I15: M2 | J15: =H15*G15 -> 13350400 | K15: =J15+K14 -> 64457400
C16: CỬA LƯỚI MV INOX 304 (RAY U80) - CL6 (TRỌN BỘ) Thương hiệu Alumdoor, Ống phi 12.7mm dày 1.0 | D16: 3.5 | E16: 4.76 | F16: 1 | G16: =E16*D16 -> 16.66 | H16: 1490000 | I16: M2 | J16: =H16*G16 -> 24823400 | K16: =J16+K15 -> 89280800
C17: CỬA LƯỚI MV INOX 304 (RAY U100 - TRỤC 140) - CL2 +CL4 (TRỌN BỘ) Thương hiệu Alumdoor, Ống phi 12.7mm dày 1.0 | D17: 3.5 | E17: 6.4 | F17: 2 | G17: =E17*D17 -> 22.4 | H17: 1490000 | I17: M2 | J17: =H17*G17*F17 -> 66752000 | K17: =J17+K16 -> 156032800
C18: CỬA LƯỚI MV INOX 304 (RAY U80) - CL5 (TRỌN BỘ) Thương hiệu Alumdoor, Ống phi 12.7mm dày 1.0 | D18: 3.5 | E18: 4.01 | F18: 1 | G18: =E18*D18 -> 14.035 | H18: 1490000 | I18: M2 | J18: =H18*G18 -> 20912150 | K18: =J18+K17 -> 176944950
C19: AL501N- MS: "chưa có" Cửa Đức Alumdoor Độ dày 1.0-1.3mm, 2 vis - 2 ron giảm chấn | D19: 3.2 | E19: 5.15 | F19: 3 | G19: =E19*D19*F19 -> 49.44 | H19: 1066000 | I19: M2 | J19: =H19*F19*G19 -> 158109120 | K19: =J19+K18 -> 335054070
C20: CK 15% | F20: 3 | G20: =G19 -> 49.44 | H20: =H19*-15% -> -159900 | I20: M2 | J20: =H20*G20 -> -7905456 | K20: =J20+K19 -> 327148614
C21: BỘ TỰ DỪNG | F21: 3 | H21: 80000 | I21: BỘ | J21: =H21*F21 -> 240000 | K21: =J21+K20 -> 327388614
C22: RAY HỘP TD | D22: 3.1 | F22: 6 | H22: 165000 | I22: M | J22: =H22*F22*D22 -> 3069000 | K22: =J22+K21 -> 330457614
C23: TRỤC 114 | E23: 5.3 | F23: 3 | H23: 140000 | I23: M | J23: =H23*F23*E23 -> 2226000 | K23: =J23+K22 -> 332683614
C24: CON LĂN | F24: 3 | H24: 90000 | I24: CẶP | J24: =H24*F24 -> 270000 | K24: =J24+K23 -> 332953614
C25: PULY LỚN | F25: 24 | H25: 24000 | I25: CÁI | J25: =H25*F25 -> 576000 | K25: =J25+K24 -> 333529614 | N25: =SUM(J19:J25) -> 156584664 | O25: =G19*F19 -> 148.32 | P25: =N25/O25 -> 1055721.8
B26: TỔNG ĐƠN HÀNG | J26: =SUM(J14:J25) -> 333529614
B28: ● Ngân hàng TMCP Quân đội (MB Bank) | H28: TP.HCM, Ngày 06 tháng 10 năm 2025
B29: Số TK 7030102681004 - Chủ TK LÊ MỘNG THUÝ | I29: Bên bán
B30: ● Ngân hàng Techcombank | F30: CÔNG TY TNHH INTERNATIONAL ALUMINUM APPLICATION (IAA) | U30: 2409000
B31: Số TK 19034379719018 - Chủ TK LÊ MỘNG THUÝ
B32: ● Ngân hàng ACB
B33: Số TK 8889886 - Chủ TK LÊ MỘNG THUÝ
C34: Cám ơn sự tin tưởng của khách hàng dành cho chúng tôi!

Sheet Sheet1
D2: CHUYÊN SẢN XUẤT: CỬA CUỐN CÔNG NGHỆ ÚC/ ĐỨC - CỬA MẮT VÕNG/ SONG NGANG
D3: Văn phòng & nhà xưởng: Số 12B đường số 2, P. Bình Hưng Hòa, Q. Bình Tân, TP.HCM
D4: Điện thoại: 096 515 9595 - 0907 939 989
D5: Website: www.alumdoor.vn
B7: BẢNG BÁO GIÁ
B9: Tên khách hàng: | C9: CTY SÁU HỒNG | G9: Ngày đặt hàng: | I9: Số hóa đơn:
B10: Điện thoại: | G10: Ngày giao hàng: | I10: Số đơn đặt hàng:
B11: Địa chỉ giao hàng: | G11: Phụ trách bán hàng: Lê Thúy
B13: NGÀY GIAO HÀNG | C13: SẢN PHẨM & QUY CÁCH | D13: CAO PHỦ BÌ (M) | E13: RỘNG NHỰA (M) | F13: SỐ LƯỢNG | G13: KHỐI LƯỢNG | H13: ĐƠN GIÁ | I13: ĐVT | J13: THÀNH TIỀN | K13: CÒN LẠI
C14: AL50 - MS: "BÁO SAU" | D14: 2.9 | E14: 4.21 | F14: 1 | G14: =E14*D14 -> 12.209 | H14: 1352000 | I14: M2 | J14: =H14*G14 -> 16506568 | K14: =J14 -> 16506568
C15: CK 15% | F15: 1 | G15: =G14 -> 12.209 | H15: =H14*-15% -> -202800 | I15: M2 | J15: =H15*G15 -> -2475985.2 | K15: =J15+K14 -> 14030583
C16: RAY HỘP TD | D16: 2.8 | F16: 2 | H16: 165000 | I16: M | J16: =H16*F16*D16 -> 924000 | K16: =J16+K14 -> 17430568
C17: PULY 114 LỚN | F17: 6 | H17: 24000 | I17: CÁI | J17: =H17*F17 -> 144000 | K17: =J17+K15 -> 14174583
C18: BỘ TỰ DỪNG | F18: 1 | H18: 80000 | I18: BỘ | J18: =H18 -> 80000 | K18: =J18+K17 -> 14254583
C19: CON LĂN | F19: 1 | H19: 90000 | I19: CẶP | J19: =H19*F19 -> 90000 | K19: =J19+K18 -> 14344583
B20: TỔNG ĐƠN HÀNG | J20: =SUM(J14:J19) -> 15268583
B22: ● Ngân hàng TMCP Quân đội (MB Bank) | H22: TP.HCM, Ngày 18 tháng 10 năm 2025
B23: Số TK 7030102681004 - Chủ TK LÊ MỘNG THUÝ | I23: Bên bán
B24: ● Ngân hàng Techcombank | F24: CÔNG TY TNHH INTERNATIONAL ALUMINUM APPLICATION (IAA) | U24: 2409000
B25: Số TK 19034379719018 - Chủ TK LÊ MỘNG THUÝ
B26: ● Ngân hàng ACB
B27: Số TK 8889886 - Chủ TK LÊ MỘNG THUÝ
C28: Cám ơn sự tin tưởng của khách hàng dành cho chúng tôi!

Sheet T4
D2: CHUYÊN SẢN XUẤT: CỬA CUỐN CÔNG NGHỆ ÚC/ ĐỨC - CỬA MẮT VÕNG/ SONG NGANG
D3: Văn phòng & nhà xưởng: Số 12B đường số 2, P. Bình Hưng Hòa, Q. Bình Tân, TP.HCM
D4: Điện thoại: 096 515 9595 - 0907 939 989
D5: Website: www.alumdoor.vn
B7: BẢNG BÁO GIÁ
B9: Tên khách hàng: | C9: CTY SÁU HỒNG | G9: Ngày đặt hàng: 18/2/2025 | I9: Số hóa đơn:
B10: Điện thoại: | G10: Ngày giao hàng: | I10: Số đơn đặt hàng:
B11: Địa chỉ giao hàng: | G11: Phụ trách bán hàng: Lê Thúy
B13: NGÀY GIAO HÀNG | C13: SẢN PHẨM & QUY CÁCH | D13: CAO PHỦ BÌ (M) | E13: RỘNG PB NHỰA(M) | F13: SỐ LƯỢNG | G13: KHỐI LƯỢNG | H13: ĐƠN GIÁ | I13: ĐVT | J13: THÀNH TIỀN | K13: CÒN LẠI
B14: 45722 | C14: AL71 | D14: 3.3 | E14: 3.69 | F14: 1 | G14: =E14*D14 -> 12.177 | H14: 965000 | I14: M2 | J14: =H14*G14 -> 11750805 | K14: =J14 -> 11750805
C15: CK 15% | F15: 1 | G15: =G14 -> 12.177 | H15: =H14*-15% -> -144750 | I15: M2 | J15: =H15*G15 -> -1762620.8 | K15: =J15+K14 -> 9988184.2
C16: BỘ TỰ DỪNG | F16: 1 | H16: 80000 | I16: BỘ | J16: =H16 -> 80000 | K16: =J16+K15 -> 10068184
C17: RAY HỘP TD | D17: 3.2 | F17: 2 | H17: 150000 | I17: M | J17: =H17*F17*D17 -> 960000 | K17: =J17+K16 -> 11028184
C18: PULY NHỎ | F18: 5 | H18: 19000 | I18: CÁI | J18: =H18*F18 -> 95000 | K18: =J18+K17 -> 11123184
B19: 45726 | C19: AL-VIPST500 | D19: 3.3 | E19: 3.79 | F19: 1 | G19: =E19*D19 -> 12.507 | H19: 1843000 | I19: M2 | J19: =H19*G19 -> 23050401 | K19: =J19+K18 -> 34173585
C20: CK 15% | F20: 1 | G20: =G19 -> 12.507 | H20: =H19*-15% -> -276450 | I20: M2 | J20: =H20*G20 -> -3457560.1 | K20: =J20+K19 -> 30716025
C21: BỘ TỰ DỪNG | F21: 1 | H21: 80000 | I21: BỘ | J21: =H21 -> 80000 | K21: =J21+K20 -> 30796025
C22: RAY HỘP TD | D22: 3.2 | F22: 2 | H22: 150000 | I22: M | J22: =H22*F22*D22 -> 960000 | K22: =J22+K21 -> 31756025
C23: PULY NHỎ | F23: 6 | H23: 19000 | I23: CÁI | J23: =H23*F23 -> 114000 | K23: =J23+K22 -> 31870025
C24: CON LĂN | F24: 1 | H24: 90000 | I24: CẶP | J24: =H24 -> 90000 | K24: =J24+K23 -> 31960025
B25: 45733 | C25: AL-548C | D25: 3.3 | E25: 3.49 | F25: 1 | G25: =E25*D25 -> 11.517 | H25: 1058000 | I25: M2 | J25: =H25*G25 -> 12184986 | K25: =J25+K24 -> 44145011
C26: CK 15% | F26: 1 | G26: =G25 -> 11.517 | H26: =H25*-15% -> -158700 | I26: M2 | J26: =H26*G26 -> -1827747.9 | K26: =J26+K25 -> 42317263
C27: AL-503N | D27: 3 | E27: 3.39 | F27: 1 | G27: =E27*D27 -> 10.17 | H27: 1004000 | I27: M2 | J27: =H27*G27 -> 10210680 | K27: =J27+K26 -> 52527943
C28: CK 15% | F28: 1 | G28: =G27 -> 10.17 | H28: =H27*-15% -> -150600 | I28: M2 | J28: =H28*G28 -> -1531602 | K28: =J28+K27 -> 50996341
C29: BỘ TỰ DỪNG | F29: 2 | H29: 80000 | I29: BỘ | J29: =H29*F29 -> 160000 | K29: =J29+K28 -> 51156341
C30: RAY HỘP TD | D30: 3.2 | F30: 2 | H30: 150000 | I30: M | J30: =H30*F30*D30 -> 960000 | K30: =J30+K29 -> 52116341
C31: RAY HỘP TD | D31: 2.9 | F31: 2 | H31: 150000 | I31: M | J31: =H31*F31*D31 -> 870000 | K31: =J31+K30 -> 52986341
C32: PULY NHỎ | F32: 10 | H32: 19000 | I32: CÁI | J32: =H32*F32 -> 190000 | K32: =J32+K31 -> 53176341
C33: CON LĂN | F33: 1 | H33: 90000 | I33: CẶP | J33: =H33 -> 90000 | K33: =J33+K32 -> 53266341
B34: 45747 | C34: BỌ AL752 | F34: 50 | H34: 2500 | I34: CON | J34: =H34*F34 -> 125000 | K34: =J34+K33 -> 53391341
C35: VÂN CHUYỂN | J35: 50000 | K35: =J35+K34 -> 53441341
B36: 45752 | C36: AL-503N | D36: 4.53 | E36: 3.94 | F36: 1 | G36: =E36*D36 -> 17.8482 | H36: 1004000 | I36: M2 | J36: =H36*G36 -> 17919593 | K36: =J36+K35 -> 71360934
C37: CK 15% | F37: 1 | G37: =G36 -> 17.8482 | H37: =H36*-15% -> -150600 | I37: M2 | J37: =H37*G37 -> -2687938.9 | K37: =J37+K36 -> 68672995
C38: BỘ TỰ DỪNG | F38: 1 | H38: 80000 | I38: BỘ | J38: =H38*F38 -> 80000 | K38: =J38+K37 -> 68752995
C39: RAY HỘP TD | D39: 4.5 | F39: 2 | H39: 150000 | I39: M | J39: =H39*F39*D39 -> 1350000 | K39: =J39+K38 -> 70102995
C40: PULY NHỎ | F40: 6 | H40: 19000 | I40: CÁI | J40: =H40*F40 -> 114000 | K40: =J40+K39 -> 70216995
C41: CON LĂN | F41: 1 | H41: 90000 | I41: CẶP | J41: =H41 -> 90000 | K41: =J41+K40 -> 70306995
B42: 45771 | C42: Thanh toán ACB | J42: -30000000 | K42: =J42+K41 -> 40306995
B43: TỔNG ĐƠN HÀNG | J43: =SUM(J14:J42) -> 40306995
B45: ● Ngân hàng TMCP Quân đội (MB Bank) | H45: TP.HCM, Ngày 18 tháng 02 năm 2025
...

Sheet T5
D2: CHUYÊN SẢN XUẤT: CỬA CUỐN CÔNG NGHỆ ÚC/ ĐỨC - CỬA MẮT VÕNG/ SONG NGANG
D3: Văn phòng & nhà xưởng: Số 12B đường số 2, P. Bình Hưng Hòa, Q. Bình Tân, TP.HCM
D4: Điện thoại: 096 515 9595 - 0907 939 989
D5: Website: www.alumdoor.vn
B7: BẢNG BÁO GIÁ
B9: Tên khách hàng: | C9: CTY SÁU HỒNG | G9: Ngày đặt hàng: 18/2/2025 | I9: Số hóa đơn:
B10: Điện thoại: | G10: Ngày giao hàng: | I10: Số đơn đặt hàng:
B11: Địa chỉ giao hàng: | G11: Phụ trách bán hàng: Lê Thúy
B13: NGÀY GIAO HÀNG | C13: SẢN PHẨM & QUY CÁCH | D13: CAO PHỦ BÌ (M) | E13: RỘNG PB NHỰA(M) | F13: SỐ LƯỢNG | G13: KHỐI LƯỢNG | H13: ĐƠN GIÁ | I13: ĐVT | J13: THÀNH TIỀN | K13: CÒN LẠI
B14: CÔNG NỢ CŨ CÒN LẠI | J14: =K14 -> 40306995 | K14: ='T4'!J43 -> 40306995 | M14: AL70 CPB 3M83 X RPBR 3M76 GS TD
B15: 45768 | C15: AL503N - MS: GS | D15: 3.4 | E15: 3.09 | F15: 1 | G15: =E15*D15 -> 10.506 | H15: 1004000 | I15: M2 | J15: =H15*G15 -> 10548024 | K15: =J15+K14 -> 50855019 | M15: AL70 CPB 3M83 X RPBR 4M05 GS TD
C16: CK 15% | F16: 1 | G16: =G15 -> 10.506 | H16: =H15*-15% -> -150600 | I16: M2 | J16: =H16*G16 -> -1582203.6 | K16: =J16+K15 -> 49272815 | M16: AL70 CPB 3M35 X RPBR 5M05 GS TD
C17: BỘ TỰ DỪNG | F17: 1 | H17: 80000 | I17: BỘ | J17: =H17*F17 -> 80000 | K17: =J17+K16 -> 49352815
C18: PULY NHỎ | F18: 4 | H18: 19000 | I18: CÁI | J18: =H18*F18 -> 76000 | K18: =J18+K17 -> 49428815 | M18: RAY HỘP 3M8 X 2 CẶP
C19: CON LĂN | F19: 1 | H19: 90000 | I19: CẶP | J19: =H19 -> 90000 | K19: =J19+K18 -> 49518815 | M19: RAY HỘP 3M3 X 1 CẶP
C20: RAY HỘP TD | D20: 3.3 | F20: 2 | H20: 150000 | I20: M2 | J20: =H20*F20*D20 -> 990000 | K20: =J20+K19 -> 50508815 | M20: PULY LỚN X 17 CÁI
B21: 45769 | C21: UPS E800i | F21: 1 | H21: 1700000 | I21: CÁI | J21: =H21 -> 1700000 | K21: =J21+K20 -> 52208815 | M21: CON LĂN X 3 CẶP
C22: Vận chuyển | F22: 1 | H22: 80000 | I22: chuyến | J22: =H22 -> 80000 | K22: =J22+K21 -> 52288815 | M22: MOTOR AC 600KG X 1 BỘ
B23: 45772 | C23: AL503N - MS: GS | D23: 3.4 | E23: 2.77 | F23: 1 | G23: =E23*D23 -> 9.418 | H23: 1004000 | I23: M2 | J23: =H23*G23 -> 9455672 | K23: =J23+K22 -> 61744487 | M23: BÌNH LƯU ĐIỆN E800I X 1 BỘ
C24: CK 15% | F24: 1 | G24: =G23 -> 9.418 | H24: =H23*-15% -> -150600 | I24: M2 | J24: =H24*G24 -> -1418350.8 | K24: =J24+K23 -> 60326137 | M24: AL503N CPB 3M4 X RPBR 2M98 GS TD
C25: BỘ TỰ DỪNG | F25: 1 | H25: 80000 | I25: BỘ | J25: =H25*F25 -> 80000 | K25: =J25+K24 -> 60406137
C26: PULY NHỎ | F26: 4 | H26: 19000 | I26: CÁI | J26: =H26*F26 -> 76000 | K26: =J26+K25 -> 60482137
C27: CON LĂN | F27: 1 | H27: 90000 | I27: CẶP | J27: =H27 -> 90000 | K27: =J27+K26 -> 60572137
C28: RAY HỘP TD | D28: 3.3 | F28: 2 | H28: 150000 | I28: M2 | J28: =H28*F28*D28 -> 990000 | K28: =J28+K27 -> 61562137
B29: 45775 | C29: AL503N - MS: GS | D29: 3.4 | E29: 2.96 | F29: 1 | G29: =E29*D29 -> 10.064 | H29: 1004000 | I29: M2 | J29: =H29*G29 -> 10104256 | K29: =J29+K28 -> 71666393
C30: CK 15% | F30: 1 | G30: =G29 -> 10.064 | H30: =H29*-15% -> -150600 | I30: M2 | J30: =H30*G30 -> -1515638.4 | K30: =J30+K29 -> 70150754
C31: BỘ TỰ DỪNG | F31: 1 | H31: 80000 | I31: BỘ | J31: =H31*F31 -> 80000 | K31: =J31+K30 -> 70230754
C32: PULY NHỎ | F32: 4 | H32: 19000 | I32: CÁI | J32: =H32*F32 -> 76000 | K32: =J32+K31 -> 70306754
C33: CON LĂN | F33: 1 | H33: 90000 | I33: CẶP | J33: =H33 -> 90000 | K33: =J33+K32 -> 70396754
C34: RAY HỘP TD | D34: 3.3 | F34: 2 | H34: 150000 | I34: M2 | J34: =H34*F34*D34 -> 990000 | K34: =J34+K33 -> 71386754
B35: 45782 | C35: AL503N - MS: GS | D35: 3.3 | E35: 3.77 | F35: 1 | G35: =E35*D35 -> 12.441 | H35: 1004000 | I35: M2 | J35: =H35*G35 -> 12490764 | K35: =J35+K34 -> 83877518
C36: CK 15% | F36: 1 | G36: =G35 -> 12.441 | H36: =H35*-15% -> -150600 | I36: M2 | J36: =H36*G36 -> -1873614.6 | K36: =J36+K35 -> 82003904
C37: BỘ TỰ DỪNG | F37: 1 | H37: 80000 | I37: BỘ | J37: =H37*F37 -> 80000 | K37: =J37+K36 -> 82083904
C38: PULY NHỎ | F38: 5 | H38: 19000 | I38: CÁI | J38: =H38*F38 -> 95000 | K38: =J38+K37 -> 82178904
C39: CON LĂN | F39: 1 | H39: 90000 | I39: CẶP | J39: =H39 -> 90000 | K39: =J39+K38 -> 82268904
C40: RAY HỘP TD | D40: 3.2 | F40: 2 | H40: 150000 | I40: M2 | J40: =H40*F40*D40 -> 960000 | K40: =J40+K39 -> 83228904
B41: 45783 | C41: AL70 - MS:GS | D41: 3.83 | E41: 3.7 | F41: 1 | G41: =E41*D41 -> 14.171 | H41: 755000 | I41: M2 | J41: =H41*G41 -> 10699105 | K41: =J41+K40 -> 93928009
C42: AL70 - MS:GS | D42: 3.83 | E42: 3.99 | F42: 1 | G42: =E42*D42 -> 15.2817 | H42: 755000 | I42: M2 | J42: =H42*G42 -> 11537684 | K42: =J42+K41 -> 1.0546569e+08
C43: AL70 - MS:GS | D43: 3.35 | E43: 4.99 | F43: 1 | G43: =E43*D43 -> 16.7165 | H43: 755000 | I43: M2 | J43: =H43*G43 -> 12620958 | K43: =J43+K42 -> 1.1808665e+08
C44: CK 15% | F44: 3 | G44: =G43+G42+G41 -> 46.1692 | H44: =H43*-15% -> -113250 | I44: M2 | J44: =H44*G44 -> -5228661.9 | K44: =J44+K43 -> 1.1285799e+08
...

Sheet T5.1
D2: CHUYÊN SẢN XUẤT: CỬA CUỐN CÔNG NGHỆ ÚC/ ĐỨC - CỬA MẮT VÕNG/ SONG NGANG
D3: Văn phòng & nhà xưởng: Số 12B đường số 2, P. Bình Hưng Hòa, Q. Bình Tân, TP.HCM
D4: Điện thoại: 096 515 9595 - 0907 939 989
D5: Website: www.alumdoor.vn
B7: BẢNG BÁO GIÁ
B9: Tên khách hàng: | C9: CTY SÁU HỒNG | G9: Ngày đặt hàng: 18/2/2025 | I9: Số hóa đơn:
B10: Điện thoại: | G10: Ngày giao hàng: | I10: Số đơn đặt hàng:
B11: Địa chỉ giao hàng: | G11: Phụ trách bán hàng: Lê Thúy
B13: NGÀY GIAO HÀNG | C13: SẢN PHẨM & QUY CÁCH | D13: CAO PHỦ BÌ (M) | E13: RỘNG PB NHỰA(M) | F13: SỐ LƯỢNG | G13: KHỐI LƯỢNG | H13: ĐƠN GIÁ | I13: ĐVT | J13: THÀNH TIỀN | K13: CÒN LẠI
B14: CÔNG NỢ CŨ CÒN LẠI | J14: ='T5'!J56 -> 1e+08 | K14: =J14 -> 1e+08
C15: THU HỒI CỬA (25/4) | J15: =-'T5'!J23 -> -9455672 | K15: =J15+K14 -> 90544328
C16: THU HỒI TỰ DỪNG | J16: =-'T5'!J25 -> -80000 | K16: =J16+K15 -> 90464328
C17: PHÍ THU HỒI | J17: =9455672*20% -> 1891134.4 | K17: =J17+K16 -> 92355462
C18: VẬN CHUYỂN | J18: 210000 | K18: =J18+K17 -> 92565462
B19: 45804 | C19: AL501N - MS:GS | D19: 4.18 | E19: 4.27 | F19: 2 | G19: =E19*D19 -> 17.8486 | H19: 1148000 | I19: M2 | J19: =H19*G19*F19 -> 40980386 | K19: =J19+K18 -> 1.3354585e+08
C20: CK 15% | F20: 2 | G20: =G19 -> 17.8486 | H20: =H19*-15% -> -172200 | I20: M2 | J20: =H20*F20*G20 -> -6147057.8 | K20: =J20+K19 -> 1.2739879e+08
C21: BỘ TỰ DỪNG | F21: 2 | H21: 80000 | I21: BỘ | J21: =H21*F21 -> 160000 | K21: =J21+K20 -> 1.2755879e+08
C22: RAY HỘP TD | D22: 4.1 | F22: 4 | H22: 140000 | I22: M | J22: =H22*F22*D22 -> 2296000 | K22: =J22+K21 -> 1.2985479e+08
C23: CON LĂN | F23: 2 | H23: 90000 | I23: CẶP | J23: =H23*F23 -> 180000 | K23: =J23+K22 -> 1.3003479e+08
C24: PULY NHỎ | F24: 12 | H24: 19000 | I24: CÁI | J24: =H24*F24 -> 228000 | K24: =J24+K23 -> 1.3026279e+08
B25: 45806 | C25: VIP50 - MS:GS | D25: 3.9 | E25: 7.5 | F25: 1 | G25: =E25*D25 -> 29.25 | H25: 1534000 | I25: M2 | J25: =H25*G25 -> 44869500 | K25: =J25+K24 -> 1.7513229e+08
C26: CK 15% | F26: 1 | G26: =G25 -> 29.25 | H26: =H25*-15% -> -230100 | I26: M2 | J26: =H26*F26*G26 -> -6730425 | K26: =J26+K25 -> 1.6840187e+08
C27: BỘ TỰ DỪNG | F27: 1 | H27: 80000 | I27: BỘ | J27: =H27*F27 -> 80000 | K27: =J27+K26 -> 1.6848187e+08
C28: RAY HỘP TD U100 | D28: 3.8 | F28: 2 | H28: 210000 | I28: M | J28: =H28*F28*D28 -> 1596000 | K28: =J28+K27 -> 1.7007787e+08
C29: PULY NHỎ | F29: 11 | H29: 19000 | I29: CÁI | J29: =H29*F29 -> 209000 | K29: =J29+K28 -> 1.7028687e+08
C30: AL652 - MS:GS | D30: 3.8 | E30: 4.6 | F30: 1 | G30: =E30*D30 -> 17.48 | H30: 1246000 | I30: M2 | J30: =H30*G30 -> 21780080 | K30: =J30+K29 -> 1.9206695e+08
C31: AL652 - MS:GS | D31: 3.8 | E31: 4.87 | F31: 1 | G31: =E31*D31 -> 18.506 | H31: 1246000 | I31: M2 | J31: =H31*G31 -> 23058476 | K31: =J31+K30 -> 2.1512542e+08
C32: CK 15% | F32: 1 | G32: =G31+G30 -> 35.986 | H32: =H31*-15% -> -186900 | I32: M2 | J32: =H32*F32*G32 -> -6725783.4 | K32: =J32+K31 -> 2.0839964e+08
C33: BỘ TỰ DỪNG | F33: 2 | H33: 80000 | I33: BỘ | J33: =H33*F33 -> 160000 | K33: =J33+K32 -> 2.0855964e+08
C34: RAY HỘP TD | D34: 3.7 | F34: 4 | H34: 120000 | I34: M | J34: =H34*F34*D34 -> 1776000 | K34: =J34+K33 -> 2.1033564e+08
C35: PULY NHỎ | F35: 14 | H35: 19000 | I35: CÁI | J35: =H35*F35 -> 266000 | K35: =J35+K34 -> 2.1060164e+08
B36: TỔNG ĐƠN HÀNG | J36: =SUM(J14:J35) -> 2.1060164e+08
B38: ● Ngân hàng TMCP Quân đội (MB Bank) | H38: TP.HCM, Ngày 18 tháng 02 năm 2025
B39: Số TK 7030102681004 - Chủ TK LÊ MỘNG THUÝ | I39: Bên bán
B40: ● Ngân hàng Techcombank | F40: CÔNG TY TNHH INTERNATIONAL ALUMINUM APPLICATION (IAA) | S40: 2409000
B41: Số TK 19034379719018 - Chủ TK LÊ MỘNG THUÝ
B42: ● Ngân hàng ACB
B43: Số TK 8889886 - Chủ TK LÊ MỘNG THUÝ
C44: Cám ơn sự tin tưởng của khách hàng dành cho chúng tôi!

Sheet T6
D2: CHUYÊN SẢN XUẤT: CỬA CUỐN CÔNG NGHỆ ÚC/ ĐỨC - CỬA MẮT VÕNG/ SONG NGANG
D3: Văn phòng & nhà xưởng: Số 12B đường số 2, P. Bình Hưng Hòa, Q. Bình Tân, TP.HCM
D4: Điện thoại: 096 515 9595 - 0907 939 989
D5: Website: www.alumdoor.vn
B7: BẢNG BÁO GIÁ
B9: Tên khách hàng: | C9: CTY SÁU HỒNG | G9: Ngày đặt hàng: 18/2/2025 | I9: Số hóa đơn:
B10: Điện thoại: | G10: Ngày giao hàng: | I10: Số đơn đặt hàng:
B11: Địa chỉ giao hàng: | G11: Phụ trách bán hàng: Lê Thúy
B13: NGÀY GIAO HÀNG | C13: SẢN PHẨM & QUY CÁCH | D13: CAO PHỦ BÌ (M) | E13: RỘNG PB NHỰA(M) | F13: SỐ LƯỢNG | G13: KHỐI LƯỢNG | H13: ĐƠN GIÁ | I13: ĐVT | J13: THÀNH TIỀN | K13: CÒN LẠI
B14: CÔNG NỢ CŨ CÒN LẠI | J14: ='T5.1'!J36 -> 2.1060164e+08 | K14: =J14 -> 2.1060164e+08
B15: 45806 | C15: AL501 (ĐỔI LÁ) | D15: =22*0.05 -> 1.1 | E15: 4.85 | F15: 1 | G15: =E15*D15 -> 5.335 | H15: 1155000 | I15: M2 | J15: =H15*G15 -> 6161925 | K15: =K14+J15 -> 2.1676356e+08
C16: HỖ TRỢ | J16: -2000000 | K16: =J16+K15 -> 2.1476356e+08
B17: 45811 | C17: AL548N | D17: 3.6 | E17: 5.79 | F17: 1 | G17: =E17*D17 -> 20.844 | H17: 1090000 | I17: M2 | J17: =H17*G17 -> 22719960 | K17: =J17+K16 -> 2.3748352e+08
C18: CK 15% | F18: 1 | G18: =G17 -> 20.844 | H18: =H17*-15% -> -163500 | I18: M2 | J18: =H18*G18 -> -3407994 | K18: =J18+K17 -> 2.3407553e+08
C19: BỘ TỰ DỪNG | F19: 1 | H19: 80000 | I19: BỘ | J19: =H19 -> 80000 | K19: =J19+K18 -> 2.3415553e+08
C20: RAY HỘP TD | D20: 3.5 | F20: 2 | H20: 140000 | I20: M | J20: =H20*F20*D20 -> 980000 | K20: =J20+K19 -> 2.3513553e+08
C21: PULY NHỎ | F21: 8 | H21: 19000 | I21: CÁI | J21: =H21*F21 -> 152000 | K21: =J21+K20 -> 2.3528753e+08
C22: CON LĂN | F22: 1 | H22: 90000 | I22: CẶP | J22: =H22 -> 90000 | K22: =J22+K21 -> 2.3537753e+08
B23: 45821 | C23: CỬA ÚC MTN 4.6D GU-VK | D23: 3.15 | E23: 3.18 | F23: 1 | G23: =E23*D23 -> 10.017 | H23: 350000 | I23: M2 | J23: =H23*G23 -> 3505950 | K23: =J23+K22 -> 2.3888348e+08
C24: RAY SẮT (KHÔNG LẤY) | D24: 3 | F24: 2 | H24: -40000 | I24: M | J24: =H24*F24*D24 -> -240000 | K24: =J24+K23 -> 2.3864348e+08
C25: TIỀN CHÀNH LẤY LẠI BỘ CỬA | J25: 210000 | K25: =J25+K24 -> 2.3885348e+08
C26: SƠN LẠI BỘ CỬA | J26: 960000 | K26: =J26+K25 -> 2.3981348e+08
B27: 45822 | C27: THANH TOÁN ACB | J27: -39813479 | K27: =J27+K26 -> 2e+08
B28: TỔNG ĐƠN HÀNG | J28: =SUM(J14:J27) -> 2e+08
B30: ● Ngân hàng TMCP Quân đội (MB Bank) | H30: TP.HCM, Ngày 18 tháng 02 năm 2025
B31: Số TK 7030102681004 - Chủ TK LÊ MỘNG THUÝ | I31: Bên bán
B32: ● Ngân hàng Techcombank | F32: CÔNG TY TNHH INTERNATIONAL ALUMINUM APPLICATION (IAA) | S32: 2409000
B33: Số TK 19034379719018 - Chủ TK LÊ MỘNG THUÝ
B34: ● Ngân hàng ACB
B35: Số TK 8889886 - Chủ TK LÊ MỘNG THUÝ
C36: Cám ơn sự tin tưởng của khách hàng dành cho chúng tôi!

Sheet T6.2
D2: CHUYÊN SẢN XUẤT: CỬA CUỐN CÔNG NGHỆ ÚC/ ĐỨC - CỬA MẮT VÕNG/ SONG NGANG
D3: Văn phòng & nhà xưởng: Số 12B đường số 2, P. Bình Hưng Hòa, Q. Bình Tân, TP.HCM
D4: Điện thoại: 096 515 9595 - 0907 939 989
D5: Website: www.alumdoor.vn
B7: BẢNG TÍNH TIỀN
B9: Tên khách hàng: | C9: CTY SÁU HỒNG | G9: Ngày đặt hàng: 18/2/2025 | I9: Số hóa đơn:
B10: Điện thoại: | G10: Ngày giao hàng: | I10: Số đơn đặt hàng:
B11: Địa chỉ giao hàng: | G11: Phụ trách bán hàng: Lê Thúy
B13: NGÀY GIAO HÀNG | C13: SẢN PHẨM & QUY CÁCH | D13: CAO PHỦ BÌ (M) | E13: RỘNG PB NHỰA(M) | F13: SỐ LƯỢNG | G13: KHỐI LƯỢNG | H13: ĐƠN GIÁ | I13: ĐVT | J13: THÀNH TIỀN | K13: CÒN LẠI
B14: CÔNG NỢ CŨ CÒN LẠI | J14: ='T6'!J28 -> 2e+08 | K14: =J14 -> 2e+08
B15: 45825 | C15: AL70 (KÉO TAY) - MS: GS | D15: 2.5 | E15: 2.4 | F15: 1 | G15: =E15*D15 -> 6 | H15: 770000 | I15: M2 | J15: =H15*G15 -> 4620000 | K15: =J15+K14 -> 2.0462e+08
C16: KHÓA NGANG | F16: 1 | H16: 250000 | I16: BỘ | J16: =H16 -> 250000 | K16: =J16+K15 -> 2.0487e+08
B17: 45825 | C17: THANH TOÁN | J17: -34870000 | K17: =J17+K16 -> 1.7e+08
B18: TỔNG ĐƠN HÀNG | J18: =SUM(J14:J17) -> 1.7e+08
B20: ● Ngân hàng TMCP Quân đội (MB Bank) | H20: TP.HCM, Ngày 18 tháng 02 năm 2025
B21: Số TK 7030102681004 - Chủ TK LÊ MỘNG THUÝ | I21: Bên bán
B22: ● Ngân hàng Techcombank | F22: CÔNG TY TNHH INTERNATIONAL ALUMINUM APPLICATION (IAA) | S22: 2409000
B23: Số TK 19034379719018 - Chủ TK LÊ MỘNG THUÝ
B24: ● Ngân hàng ACB
B25: Số TK 8889886 - Chủ TK LÊ MỘNG THUÝ
C26: Cám ơn sự tin tưởng của khách hàng dành cho chúng tôi!

Sheet T7
D2: CHUYÊN SẢN XUẤT: CỬA CUỐN CÔNG NGHỆ ÚC/ ĐỨC - CỬA MẮT VÕNG/ SONG NGANG
D3: Văn phòng & nhà xưởng: Số 12B đường số 2, P. Bình Hưng Hòa, Q. Bình Tân, TP.HCM
D4: Điện thoại: 096 515 9595 - 0907 939 989
D5: Website: www.alumdoor.vn
B7: BẢNG TÍNH TIỀN
B9: Tên khách hàng: | C9: CTY SÁU HỒNG | G9: Ngày đặt hàng: | I9: Số hóa đơn:
B10: Điện thoại: | G10: Ngày giao hàng: | I10: Số đơn đặt hàng:
B11: Địa chỉ giao hàng: | G11: Phụ trách bán hàng: Lê Thúy
B13: NGÀY GIAO HÀNG | C13: SẢN PHẨM & QUY CÁCH | D13: CAO PHỦ BÌ (M) | E13: RỘNG PB NHỰA(M) | F13: SỐ LƯỢNG | G13: KHỐI LƯỢNG | H13: ĐƠN GIÁ | I13: ĐVT | J13: THÀNH TIỀN | K13: CÒN LẠI
B14: CÔNG NỢ CŨ CÒN LẠI | J14: ='T6.2'!J18 -> 1.7e+08 | K14: =J14 -> 1.7e+08
B15: 45825 | C15: RAY ĐƠN (BỘ AL70) | D15: 2.4 | F15: 2 | H15: 120000 | I15: M | J15: =H15*F15*D15 -> 576000 | K15: =J15+K14 -> 1.70576e+08
C16: VÍT ĐẦU LÔ X 10KG | F16: 10 | H16: 65000 | I16: KG | J16: =H16*F16 -> 650000 | K16: =J16+K15 -> 1.71226e+08
B17: 45847 | C17: AL503 MS: GS | D17: 3.33 | E17: 2.79 | F17: 1 | G17: =E17*D17 -> 9.2907 | H17: 987000 | I17: M2 | J17: =H17*G17 -> 9169920.9 | K17: =J17+K16 -> 1.8039592e+08
C18: CK 15% | F18: 1 | G18: =G17 -> 9.2907 | H18: =H17*-15% -> -148050 | I18: M2 | J18: =H18*G18 -> -1375488.1 | K18: =J18+K17 -> 1.7902043e+08
C19: BỘ TỰ DỪNG | F19: 1 | H19: 80000 | I19: BỘ | J19: =H19 -> 80000 | K19: =J19+K18 -> 1.7910043e+08
C20: RAY HỘP TD | D20: 2.4 | F20: 2 | H20: 140000 | I20: M | J20: =H20*F20*D20 -> 672000 | K20: =J20+K19 -> 1.7977243e+08
C21: PULY LỚN | F21: 4 | H21: 24000 | I21: CÁI | J21: =H21*F21 -> 96000 | K21: =J21+K20 -> 1.7986843e+08
B22: 45848 | C22: AL548 CPB 2M4 X RPBR 2M6 GS TD | D22: 2.4 | E22: 2.54 | F22: 1 | G22: =E22*D22 -> 6.096 | H22: 1090000 | I22: M2 | J22: =H22*G22 -> 6644640 | K22: =J22+K21 -> 1.8651307e+08
C23: CK 15% | F23: 1 | G23: =G22 -> 6.096 | H23: =H22*-15% -> -163500 | I23: M2 | J23: =H23*G23 -> -996696 | K23: =J23+K22 -> 1.8551638e+08
C24: BỘ TỰ DỪNG | F24: 1 | H24: 80000 | I24: BỘ | J24: =H24 -> 80000 | K24: =J24+K23 -> 1.8559638e+08
C25: RAY HỘP TD | D25: 2.3 | F25: 2 | H25: 140000 | I25: M | J25: =H25*F25*D25 -> 644000 | K25: =J25+K24 -> 1.8624038e+08
C26: PULY NHỎ | F26: 4 | H26: 19000 | I26: CÁI | J26: =H26*F26 -> 76000 | K26: =J26+K25 -> 1.8631638e+08
C27: CON LĂN | F27: 1 | H27: 90000 | I27: CẶP | J27: =H27 -> 90000 | K27: =J27+K26 -> 1.8640638e+08
B28: 45868 | C28: THANH TOÁN ACB | J28: -50000000 | K28: =J28+K27 -> 1.3640638e+08
B29: TỔNG ĐƠN HÀNG | J29: =SUM(J14:J28) -> 1.3640638e+08
B31: ● Ngân hàng TMCP Quân đội (MB Bank) | H31: TP.HCM, Ngày 18 tháng 07 năm 2025
B32: Số TK 7030102681004 - Chủ TK LÊ MỘNG THUÝ | I32: Bên bán
B33: ● Ngân hàng Techcombank | F33: CÔNG TY TNHH INTERNATIONAL ALUMINUM APPLICATION (IAA) | S33: 2409000
B34: Số TK 19034379719018 - Chủ TK LÊ MỘNG THUÝ
B35: ● Ngân hàng ACB
B36: Số TK 8889886 - Chủ TK LÊ MỘNG THUÝ
C37: Cám ơn sự tin tưởng của khách hàng dành cho chúng tôi!

Sheet T7-8
D2: CHUYÊN SẢN XUẤT: CỬA CUỐN CÔNG NGHỆ ÚC/ ĐỨC - CỬA MẮT VÕNG/ SONG NGANG
D3: Văn phòng & nhà xưởng: Số 12B đường số 2, P. Bình Hưng Hòa, Q. Bình Tân, TP.HCM
D4: Điện thoại: 096 515 9595 - 0907 939 989
D5: Website: www.alumdoor.vn
B7: BẢNG TÍNH TIỀN
B9: Tên khách hàng: | C9: CTY SÁU HỒNG | G9: Ngày đặt hàng: | I9: Số hóa đơn:
B10: Điện thoại: | G10: Ngày giao hàng: | I10: Số đơn đặt hàng:
B11: Địa chỉ giao hàng: | G11: Phụ trách bán hàng: Lê Thúy
B13: NGÀY GIAO HÀNG | C13: SẢN PHẨM & QUY CÁCH | D13: CAO PHỦ BÌ (M) | E13: RỘNG PB NHỰA(M) | F13: SỐ LƯỢNG | G13: KHỐI LƯỢNG | H13: ĐƠN GIÁ | I13: ĐVT | J13: THÀNH TIỀN | K13: CÒN LẠI
B14: CÔNG NỢ CŨ CÒN LẠI | J14: ='T7'!J29 -> 1.3640638e+08 | K14: =J14 -> 1.3640638e+08
B15: 45857 | C15: TI INOX 6M | F15: 100 | H15: 48000 | I15: CÂY | J15: =H15*F15 -> 4800000 | K15: =J15+K14 -> 1.4120638e+08
B16: 45861 | C16: RAY HỘP TD | D16: 3 | F16: 2 | H16: 150000 | I16: M | J16: =H16*F16*D16 -> 900000 | K16: =J16+K15 -> 1.4210638e+08
C17: VẬN CHUYỂN XE ÔM | F17: 1 | H17: 200000 | I17: CHUYẾN | J17: =H17 -> 200000 | K17: =J17+K16 -> 1.4230638e+08
C18: AL503N MS: VK | D18: 3.2 | E18: 3.74 | F18: 1 | G18: =E18*D18 -> 11.968 | H18: 1014000 | I18: M2 | J18: =H18*G18 -> 12135552 | K18: =J18+K17 -> 1.5444193e+08
C19: AL503N MS: VK | D19: 2.8 | E19: 2.79 | F19: 1 | G19: =E19*D19 -> 7.812 | H19: 1014000 | I19: M2 | J19: =H19*G19 -> 7921368 | K19: =J19+K18 -> 1.623633e+08
C20: CK 15% | F20: 2 | G20: =G19+G18 -> 19.78 | H20: =H19*-15% -> -152100 | I20: M2 | J20: =H20*G20 -> -3008538 | K20: =J20+K19 -> 1.5935476e+08
C21: BỘ TỰ DỪNG | F21: 2 | H21: 80000 | I21: BỘ | J21: =H21*F21 -> 160000 | K21: =J21+K20 -> 1.5951476e+08
C22: RAY HỘP TD | D22: 3.1 | F22: 2 | H22: 150000 | I22: M | J22: =H22*F22*D22 -> 930000 | K22: =J22+K21 -> 1.6044476e+08
C23: RAY HỘP TD | D23: 2.7 | F23: 2 | H23: 150000 | I23: M | J23: =H23*F23*D23 -> 810000 | K23: =J23+K22 -> 1.6125476e+08
C24: CON LĂN | F24: 2 | H24: 90000 | I24: CẶP | J24: =H24*F24 -> 180000 | K24: =J24+K23 -> 1.6143476e+08
C25: PULY LỚN | F25: 9 | H25: 24000 | I25: CÁI | J25: =H25*F25 -> 216000 | K25: =J25+K24 -> 1.6165076e+08
B26: TỔNG ĐƠN HÀNG | J26: =SUM(J14:J25) -> 1.6165076e+08
B28: ● Ngân hàng TMCP Quân đội (MB Bank) | H28: TP.HCM, Ngày 18 tháng 07 năm 2025
B29: Số TK 7030102681004 - Chủ TK LÊ MỘNG THUÝ | I29: Bên bán
B30: ● Ngân hàng Techcombank | F30: CÔNG TY TNHH INTERNATIONAL ALUMINUM APPLICATION (IAA) | S30: 2409000
B31: Số TK 19034379719018 - Chủ TK LÊ MỘNG THUÝ
B32: ● Ngân hàng ACB
B33: Số TK 8889886 - Chủ TK LÊ MỘNG THUÝ
C34: Cám ơn sự tin tưởng của khách hàng dành cho chúng tôi!
